Workbook

Sheet Data
A1: Locality | B1: Winsome-Sears | C1: Spanberger | D1: Others | E1: Total
A2: ='Wikipedia table'!A43 -> Fairfax County | B2: ='Wikipedia table'!B43 -> 116053 | C2: ='Wikipedia table'!D43 -> 329977 | D2: ='Wikipedia table'!F43 -> 1222 | E2: =SUM(B2:D2) -> 447252
A3: ='Wikipedia table'!A30 -> Chesterfield | B3: ='Wikipedia table'!B30 -> 70021 | C3: ='Wikipedia table'!D30 -> 100595 | D3: ='Wikipedia table'!F30 -> 294 | E3: =SUM(B3:D3) -> 170910
A4: ='Wikipedia table'!A128 -> Virginia Beach | B4: ='Wikipedia table'!B128 -> 75013 | C4: ='Wikipedia table'!D128 -> 94339 | D4: ='Wikipedia table'!F128 -> 269 | E4: =SUM(B4:D4) -> 169621
A5: ='Wikipedia table'!A75 -> Loudoun | B5: ='Wikipedia table'!B75 -> 59278 | C5: ='Wikipedia table'!D75 -> 108594 | D5: ='Wikipedia table'!F75 -> 444 | E5: =SUM(B5:D5) -> 168316
A6: ='Wikipedia table'!A105 -> Prince William | B6: ='Wikipedia table'!B105 -> 54309 | C6: ='Wikipedia table'!D105 -> 111198 | D6: ='Wikipedia table'!F105 -> 381 | E6: =SUM(B6:D6) -> 165888
A7: ='Wikipedia table'!A63 -> Henrico | B7: ='Wikipedia table'!B63 -> 45627 | C7: ='Wikipedia table'!D63 -> 103559 | D7: ='Wikipedia table'!F63 -> 260 | E7: =SUM(B7:D7) -> 149446
A8: ='Wikipedia table'!A12 -> Arlington | B8: ='Wikipedia table'!B12 -> 15929 | C8: ='Wikipedia table'!D12 -> 83657 | D8: ='Wikipedia table'!F12 -> 235 | E8: =SUM(B8:D8) -> 99821
A9: ='Wikipedia table'!A29 -> Chesapeake | B9: ='Wikipedia table'!B29 -> 42147 | C9: ='Wikipedia table'!D29 -> 53971 | D9: ='Wikipedia table'!F29 -> 164 | E9: =SUM(B9:D9) -> 96282
A10: ='Wikipedia table'!A109 -> Richmond City | B10: ='Wikipedia table'!B109 -> 11883 | C10: ='Wikipedia table'!D109 -> 79019 | D10: ='Wikipedia table'!F109 -> 212 | E10: =SUM(B10:D10) -> 91114
A11: ='Wikipedia table'!A90 -> Norfolk | B11: ='Wikipedia table'!B90 -> 15509 | C11: ='Wikipedia table'!D90 -> 48599 | D11: ='Wikipedia table'!F90 -> 111 | E11: =SUM(B11:D11) -> 64219
A12: ='Wikipedia table'!A122 -> Stafford | B12: ='Wikipedia table'!B122 -> 27774 | C12: ='Wikipedia table'!D122 -> 35327 | D12: ='Wikipedia table'!F122 -> 115 | E12: =SUM(B12:D12) -> 63216
A13: ='Wikipedia table'!A7 -> Alexandria | B13: ='Wikipedia table'!B7 -> 10424 | C13: ='Wikipedia table'!D7 -> 52230 | D13: ='Wikipedia table'!F7 -> 190 | E13: =SUM(B13:D13) -> 62844
A14: ='Wikipedia table'!A61 -> Hanover | B14: ='Wikipedia table'!B61 -> 36278 | C14: ='Wikipedia table'!D61 -> 23994 | D14: ='Wikipedia table'!F61 -> 95 | E14: =SUM(B14:D14) -> 60367
A15: ='Wikipedia table'!A121 -> Spotsylvania | B15: ='Wikipedia table'!B121 -> 29015 | C15: ='Wikipedia table'!D121 -> 30748 | D15: ='Wikipedia table'!F121 -> 104 | E15: =SUM(B15:D15) -> 59867
A16: ='Wikipedia table'!A89 -> Newport News | B16: ='Wikipedia table'!B89 -> 17461 | C16: ='Wikipedia table'!D89 -> 38936 | D16: ='Wikipedia table'!F89 -> 92 | E16: =SUM(B16:D16) -> 56489
A17: ='Wikipedia table'!A6 -> Albemarle | B17: ='Wikipedia table'!B6 -> 16480 | C17: ='Wikipedia table'!D6 -> 39322 | D17: ='Wikipedia table'!F6 -> 93 | E17: =SUM(B17:D17) -> 55895
A18: ='Wikipedia table'!A60 -> Hampton | B18: ='Wikipedia table'!B60 -> 12103 | C18: ='Wikipedia table'!D60 -> 35129 | D18: ='Wikipedia table'!F60 -> 91 | E18: =SUM(B18:D18) -> 47323
A19: ='Wikipedia table'!A112 -> Roanoke County | B19: ='Wikipedia table'!B112 -> 24728 | C19: ='Wikipedia table'!D112 -> 18062 | D19: ='Wikipedia table'!F112 -> 97 | E19: =SUM(B19:D19) -> 42887
A20: ='Wikipedia table'!A68 -> James City | B20: ='Wikipedia table'!B68 -> 19029 | C20: ='Wikipedia table'!D68 -> 23603 | D20: ='Wikipedia table'!F68 -> 63 | E20: =SUM(B20:D20) -> 42695
A21: ='Wikipedia table'!A124 -> Suffolk | B21: ='Wikipedia table'!B124 -> 15935 | C21: ='Wikipedia table'!D124 -> 25696 | D21: ='Wikipedia table'!F124 -> 80 | E21: =SUM(B21:D21) -> 41711
A22: ='Wikipedia table'!A15 -> Bedford | B22: ='Wikipedia table'!B15 -> 29166 | C22: ='Wikipedia table'!D15 -> 10048 | D22: ='Wikipedia table'!F15 -> 57 | E22: =SUM(B22:D22) -> 39271
A23: ='Wikipedia table'!A50 -> Frederick | B23: ='Wikipedia table'!B50 -> 23130 | C23: ='Wikipedia table'!D50 -> 15809 | D23: ='Wikipedia table'!F50 -> 51 | E23: =SUM(B23:D23) -> 38990
A24: ='Wikipedia table'!A86 -> Montgomery | B24: ='Wikipedia table'!B86 -> 15228 | C24: ='Wikipedia table'!D86 -> 21428 | D24: ='Wikipedia table'!F86 -> 76 | E24: =SUM(B24:D24) -> 36732
A25: ='Wikipedia table'!A114 -> Rockingham | B25: ='Wikipedia table'!B114 -> 24498 | C25: ='Wikipedia table'!D114 -> 11622 | D25: ='Wikipedia table'!F114 -> 76 | E25: =SUM(B25:D25) -> 36196
A26: ='Wikipedia table'!A45 -> Fauquier | B26: ='Wikipedia table'!B45 -> 19894 | C26: ='Wikipedia table'!D45 -> 14610 | D26: ='Wikipedia table'!F45 -> 62 | E26: =SUM(B26:D26) -> 34566
A27: ='Wikipedia table'!A13 -> Augusta | B27: ='Wikipedia table'!B13 -> 24612 | C27: ='Wikipedia table'!D13 -> 9522 | D27: ='Wikipedia table'!F13 -> 60 | E27: =SUM(B27:D27) -> 34194
A28: ='Wikipedia table'!A137 -> York | B28: ='Wikipedia table'!B137 -> 15684 | C28: ='Wikipedia table'!D137 -> 15769 | D28: ='Wikipedia table'!F137 -> 47 | E28: =SUM(B28:D28) -> 31500
A29: ='Wikipedia table'!A101 -> Portsmouth | B29: ='Wikipedia table'!B101 -> 8351 | C29: ='Wikipedia table'!D101 -> 23040 | D29: ='Wikipedia table'!F101 -> 62 | E29: =SUM(B29:D29) -> 31453
A30: ='Wikipedia table'!A111 -> Roanoke City | B30: ='Wikipedia table'!B111 -> 10153 | C30: ='Wikipedia table'!D111 -> 20700 | D30: ='Wikipedia table'!F111 -> 83 | E30: =SUM(B30:D30) -> 30936
A31: ='Wikipedia table'!A78 -> Lynchburg | B31: ='Wikipedia table'!B78 -> 13508 | C31: ='Wikipedia table'!D78 -> 13231 | D31: ='Wikipedia table'!F78 -> 56 | E31: =SUM(B31:D31) -> 26795
A32: ='Wikipedia table'!A99 -> Pittsylvania | B32: ='Wikipedia table'!B99 -> 17439 | C32: ='Wikipedia table'!D99 -> 7272 | D32: ='Wikipedia table'!F99 -> 38 | E32: =SUM(B32:D32) -> 24749
A33: ='Wikipedia table'!A49 -> Franklin County | B33: ='Wikipedia table'!B49 -> 16317 | C33: ='Wikipedia table'!D49 -> 6836 | D33: ='Wikipedia table'!F49 -> 36 | E33: =SUM(B33:D33) -> 23189
A34: ='Wikipedia table'!A23 -> Campbell | B34: ='Wikipedia table'!B23 -> 16878 | C34: ='Wikipedia table'!D23 -> 6130 | D34: ='Wikipedia table'!F23 -> 34 | E34: =SUM(B34:D34) -> 23042
A35: ='Wikipedia table'!A35 -> Culpeper | B35: ='Wikipedia table'!B35 -> 12592 | C35: ='Wikipedia table'!D35 -> 9214 | D35: ='Wikipedia table'!F35 -> 33 | E35: =SUM(B35:D35) -> 21839
A36: ='Wikipedia table'!A130 -> Washington | B36: ='Wikipedia table'!B130 -> 15614 | C36: ='Wikipedia table'!D130 -> 5382 | D36: ='Wikipedia table'!F130 -> 43 | E36: =SUM(B36:D36) -> 21039
A37: ='Wikipedia table'!A67 -> Isle of Wight | B37: ='Wikipedia table'!B67 -> 10931 | C37: ='Wikipedia table'!D67 -> 8227 | D37: ='Wikipedia table'!F67 -> 37 | E37: =SUM(B37:D37) -> 19195
A38: ='Wikipedia table'!A76 -> Louisa | B38: ='Wikipedia table'!B76 -> 11279 | C38: ='Wikipedia table'!D76 -> 7628 | D38: ='Wikipedia table'!F76 -> 44 | E38: =SUM(B38:D38) -> 18951
A39: ='Wikipedia table'!A28 -> Charlottesville | B39: ='Wikipedia table'!B28 -> 2056 | C39: ='Wikipedia table'!D28 -> 16799 | D39: ='Wikipedia table'!F28 -> 35 | E39: =SUM(B39:D39) -> 18890
A40: ='Wikipedia table'!A118 -> Shenandoah | B40: ='Wikipedia table'!B118 -> 12488 | C40: ='Wikipedia table'!D118 -> 5698 | D40: ='Wikipedia table'!F118 -> 37 | E40: =SUM(B40:D40) -> 18223
...

Sheet Wikipedia table
B1: Winsome Earle-Sears | D1: Abigail Spanberger | F1: Write-in
A2: Locality[174] | B2: Republican | D2: Democratic | F2: Various
H3: Margin | J3: Total
A4: # | B4: % | C4: # | D4: % | E4: # | F4: % | G4: #
A5: Accomack | B5: 7129 | C5: 0.5457 | D5: 5925 | E5: 0.4535 | F5: 10 | G5: 0.0008 | H5: −1,204 | I5: −9.22% | J5: 13064
A6: Albemarle | B6: 16480 | C6: 0.2948 | D6: 39322 | E6: 0.7035 | F6: 93 | G6: 0.0017 | H6: 22842 | I6: 0.4087 | J6: 55895
A7: Alexandria | B7: 10424 | C7: 0.1659 | D7: 52230 | E7: 0.8311 | F7: 190 | G7: 0.003 | H7: 41806 | I7: 0.6652 | J7: 62844
A8: Alleghany | B8: 4011 | C8: 0.6914 | D8: 1779 | E8: 0.3067 | F8: 11 | G8: 0.0019 | H8: −2,232 | I8: −38.48% | J8: 5801
A9: Amelia | B9: 4521 | C9: 0.7108 | D9: 1831 | E9: 0.2879 | F9: 8 | G9: 0.0013 | H9: −2,690 | I9: −42.30% | J9: 6360
A10: Amherst | B10: 8811 | C10: 0.6713 | D10: 4294 | E10: 0.3272 | F10: 20 | G10: 0.0015 | H10: −4,517 | I10: −34.42% | J10: 13125
A11: Appomattox | B11: 5609 | C11: 0.7594 | D11: 1765 | E11: 0.239 | F11: 12 | G11: 0.0016 | H11: −3,844 | I11: −52.04% | J11: 7386
A12: Arlington | B12: 15929 | C12: 0.1596 | D12: 83657 | E12: 0.8381 | F12: 235 | G12: 0.0024 | H12: 67728 | I12: 0.6785 | J12: 99821
A13: Augusta | B13: 24612 | C13: 0.7198 | D13: 9522 | E13: 0.2785 | F13: 60 | G13: 0.0018 | H13: −15,090 | I13: −44.13% | J13: 34194
A14: Bath | B14: 1421 | C14: 0.7405 | D14: 493 | E14: 0.2569 | F14: 5 | G14: 0.0026 | H14: −928 | I14: −48.36% | J14: 1919
A15: Bedford | B15: 29166 | C15: 0.7427 | D15: 10048 | E15: 0.2559 | F15: 57 | G15: 0.0015 | H15: −19,118 | I15: −48.68% | J15: 39271
A16: Bland | B16: 1974 | C16: 0.8164 | D16: 441 | E16: 0.1824 | F16: 3 | G16: 0.0012 | H16: −1,533 | I16: −63.40% | J16: 2418
A17: Botetourt | B17: 11820 | C17: 0.7027 | D17: 4969 | E17: 0.2954 | F17: 32 | G17: 0.0019 | H17: −6,851 | I17: −40.73% | J17: 16821
A18: Bristol | B18: 3090 | C18: 0.6496 | D18: 1660 | E18: 0.349 | F18: 7 | G18: 0.0015 | H18: −1,430 | I18: −30.06% | J18: 4757
A19: Brunswick | B19: 2591 | C19: 0.4366 | D19: 3338 | E19: 0.5625 | F19: 5 | G19: 0.0008 | H19: 747 | I19: 0.1259 | J19: 5934
A20: Buchanan | B20: 4434 | C20: 0.8191 | D20: 971 | E20: 0.1794 | F20: 8 | G20: 0.0015 | H20: −3,463 | I20: −63.98% | J20: 5413
A21: Buckingham | B21: 3586 | C21: 0.5922 | D21: 2456 | E21: 0.4056 | F21: 13 | G21: 0.0021 | H21: −1,130 | I21: −18.66% | J21: 6055
A22: Buena Vista | B22: 1392 | C22: 0.6638 | D22: 696 | E22: 0.3319 | F22: 9 | G22: 0.0043 | H22: −696 | I22: −33.19% | J22: 2097
A23: Campbell | B23: 16878 | C23: 0.7325 | D23: 6130 | E23: 0.266 | F23: 34 | G23: 0.0015 | H23: −10,748 | I23: −46.65% | J23: 23042
A24: Caroline | B24: 6680 | C24: 0.4972 | D24: 6733 | E24: 0.5011 | F24: 23 | G24: 0.0017 | H24: 53 | I24: 0.0039 | J24: 13436
A25: Carroll | B25: 8889 | C25: 0.7833 | D25: 2433 | E25: 0.2144 | F25: 26 | G25: 0.0023 | H25: −6,456 | I25: −56.89% | J25: 11348
A26: Charles City | B26: 1485 | C26: 0.4253 | D26: 2002 | E26: 0.5733 | F26: 5 | G26: 0.0014 | H26: 517 | I26: 0.1481 | J26: 3492
A27: Charlotte | B27: 3159 | C27: 0.6707 | D27: 1545 | E27: 0.328 | F27: 6 | G27: 0.0013 | H27: −1,614 | I27: −34.27% | J27: 4710
A28: Charlottesville | B28: 2056 | C28: 0.1088 | D28: 16799 | E28: 0.8893 | F28: 35 | G28: 0.0019 | H28: 14743 | I28: 0.7805 | J28: 18890
A29: Chesapeake | B29: 42147 | C29: 0.4377 | D29: 53971 | E29: 0.5606 | F29: 164 | G29: 0.0017 | H29: 11824 | I29: 0.1228 | J29: 96282
A30: Chesterfield | B30: 70021 | C30: 0.4097 | D30: 100595 | E30: 0.5886 | F30: 294 | G30: 0.0017 | H30: 30574 | I30: 0.1789 | J30: 170910
A31: Clarke | B31: 4222 | C31: 0.5534 | D31: 3389 | E31: 0.4442 | F31: 18 | G31: 0.0024 | H31: −833 | I31: −10.92% | J31: 7629
A32: Colonial Heights | B32: 4092 | C32: 0.6212 | D32: 2474 | E32: 0.3756 | F32: 21 | G32: 0.0032 | H32: −1,618 | I32: −24.56% | J32: 6587
A33: Covington | B33: 999 | C33: 0.5957 | D33: 678 | E33: 0.4043 | F33: 0 | G33: 0 | H33: −321 | I33: −19.14% | J33: 1677
A34: Craig | B34: 1806 | C34: 0.7925 | D34: 467 | E34: 0.2049 | F34: 6 | G34: 0.0026 | H34: −1,339 | I34: −58.75% | J34: 2279
A35: Culpeper | B35: 12592 | C35: 0.5766 | D35: 9214 | E35: 0.4219 | F35: 33 | G35: 0.0015 | H35: −3,378 | I35: −15.47% | J35: 21839
A36: Cumberland | B36: 2609 | C36: 0.5903 | D36: 1803 | E36: 0.4079 | F36: 8 | G36: 0.0018 | H36: −806 | I36: −18.24% | J36: 4418
A37: Danville | B37: 4592 | C37: 0.3734 | D37: 7678 | E37: 0.6243 | F37: 29 | G37: 0.0024 | H37: 3086 | I37: 0.2509 | J37: 12299
A38: Dickenson | B38: 3427 | C38: 0.768 | D38: 1028 | E38: 0.2304 | F38: 7 | G38: 0.0016 | H38: −2,399 | I38: −53.77% | J38: 4462
A39: Dinwiddie | B39: 7028 | C39: 0.5819 | D39: 5031 | E39: 0.4165 | F39: 19 | G39: 0.0016 | H39: −1,997 | I39: −16.53% | J39: 12078
A40: Emporia | B40: 544 | C40: 0.3265 | D40: 1119 | E40: 0.6717 | F40: 3 | G40: 0.0018 | H40: 575 | I40: 0.3451 | J40: 1666
...
